Workbook

Sheet Promedio_Grupo_Lab
A1: Grupo | B1: Laboratorio | C1: Promedio_Nota
A2: GS123 | B2: Lab1 | C2: 88.3
A3: GS123 | B3: Lab2 | C3: 87.5
A4: GS123 | B4: Lab3 | C4: 71
A5: GS123 | B5: Lab4 | C5: 86.5
A6: GS123 | B6: Lab5 | C6: 87.9
A7: GS124 | B7: Lab1 | C7: 63.1
A8: GS124 | B8: Lab2 | C8: 64.8
A9: GS124 | B9: Lab3 | C9: 62
A10: GS124 | B10: Lab4 | C10: 67.7
A11: GS124 | B11: Lab5 | C11: 67.3
A12: GS126 | B12: Lab1 | C12: 96.1
A13: GS126 | B13: Lab2 | C13: 89.6
... A16: GS126 | B16: Lab5 | C16: 89.2

Sheet Notas_Completas
A1: ID_Estudiante | B1: Grupo | C1: Laboratorio | D1: Nota
A2: GS123-01 | B2: GS123 | C2: Lab1 | D2: 90.8
A3: GS123-01 | B3: GS123 | C3: Lab2 | D3: 83.1
A4: GS123-01 | B4: GS123 | C4: Lab3 | D4: 100
A5: GS123-01 | B5: GS123 | C5: Lab4 | D5: 93.8
A6: GS123-01 | B6: GS123 | C6: Lab5 | D6: 88.4
A7: GS123-02 | B7: GS123 | C7: Lab1 | D7: 80.1
A8: GS123-02 | B8: GS123 | C8: Lab2 | D8: 88.4
A9: GS123-02 | B9: GS123 | C9: Lab3 | D9: 89.3
A10: GS123-02 | B10: GS123 | C10: Lab4 | D10: 78.3
A11: GS123-02 | B11: GS123 | C11: Lab5 | D11: 100
A12: GS123-03 | B12: GS123 | C12: Lab1 | D12: 91.2
A13: GS123-03 | B13: GS123 | C13: Lab2 | D13: 100
... A181: GS126-12 | B181: GS126 | C181: Lab5 | D181: 90.7

Sheet Actividades_1_2
A1: Actividad 1. Análisis de los cuatro niveles – Bases de Datos II
A2: Necesidad: identificar qué grupo y qué laboratorio presentan mayor dificultad para planificar refuerzos (datos en la hoja Promedio_Grupo_Lab, A1:C16).
A4: Nivel del modelo | B4: Decisión tomada en este nivel | C4: Amenaza a la validez (si la decisión es incorrecta) | D4: Método de validación
A5: 1. Situación de dominio | B5: Usuarios: docente y coordinación de Bases de Datos II. Pregunta: ¿qué grupo (GS123, GS124, GS126) y qué laboratorio (Lab1–Lab5) tienen bajo rendimiento, para planificar refuerzos? | C5: Problema equivocado: malinterpretar la necesidad real (p. ej., que en realidad interese el rendimiento individual del estudiante y no el del grupo). | D5: Observar y entrevistar a los usuarios objetivo (docente/coordinación); medir luego la adopción de la herramienta.
A6: 2. Abstracción de tarea / datos | B6: Tarea: comparar y localizar valores extremos (mínimos) por grupo y laboratorio. Datos: tabla con 2 atributos categóricos (Grupo, Laboratorio) y 1 cuantitativo derivado (Promedio_Nota). | C6: Abstracción equivocada: mostrar algo que no responde a la necesidad (p. ej., solo el promedio general del grupo, ocultando el laboratorio problemático). | D6: Justificar la elección frente a alternativas y obtener retroalimentación de los usuarios con la herramienta en uso.
A7: 3. Idiom (codificación visual e interacción) | B7: Mapa de calor (matriz Grupo × Laboratorio con escala de color) y barras agrupadas (Laboratorio en eje X, una serie por grupo); filtros en la tabla dinámica. | C7: Idiom inefectivo: la codificación no funciona perceptualmente (colores difíciles de distinguir, barras parecidas que dificultan encontrar el mínimo). | D7: Análisis cualitativo de las imágenes; estudio de laboratorio midiendo tiempo y errores (Actividad 2); pruebas de usabilidad.
A8: 4. Algoritmo | B8: Agregación con tabla dinámica / PROMEDIO.SI.CONJUNTO y formato condicional de escala de color calculado por Excel. | C8: Algoritmo lento: el cálculo o el renderizado no escala con más estudiantes/cursos, o el resultado no es fiel al idiom especificado. | D8: Análisis de complejidad computacional y medición de tiempo y memoria; verificar exactitud del cálculo (tabla inferior).
A10: Verificación de un promedio específico (PROMEDIO.SI.CONJUNTO)
A11: Grupo | B11: Laboratorio | C11: Promedio en Promedio_Grupo_Lab | D11: Promedio recalculado desde Notas_Completas
A12: GS124 | B12: Lab3 | C12: =AVERAGEIFS(Promedio_Grupo_Lab!$C$2:$C$16,Promedio_Grupo_Lab!$A$2:$A$16,A12,Promedio_Grupo_Lab!$B$2:$B$16,B12) -> 62 | D12: =AVERAGEIFS(Notas_Completas!$D$2:$D$181,Notas_Completas!$B$2:$B$181,A12,Notas_Completas!$C$2:$C$181,B12) -> 67.1
A16: Actividad 2. Validación de idiom mediante análisis de imagen y tiempo
A17: Pregunta: ¿en qué laboratorio tuvo más dificultad el Grupo GS124?
A18: Tabla dinámica (Grupo en filas, Laboratorio en columnas, Promedio de Nota)
A19: Promedio de Nota | B19: Etiquetas de columna
A20: Etiquetas de fila | B20: Lab1 | C20: Lab2 | D20: Lab3 | E20: Lab4 | F20: Lab5
A21: GS123 | B21: 88.3 | C21: 87.5 | D21: 71 | E21: 86.5 | F21: 87.9
A22: GS124 | B22: 63.1 | C22: 64.8 | D22: 62 | E22: 67.7 | F22: 67.3
A23: GS126 | B23: 96.1 | C23: 89.6 | D23: 83.1 | E23: 89.7 | F23: 89.2
A25: Idiom B – Mapa de calor (escala de color, vinculado a la tabla dinámica)
A26: Grupo | B26: Lab1 | C26: Lab2 | D26: Lab3 | E26: Lab4 | F26: Lab5
A27: GS123 | B27: =GETPIVOTDATA("Promedio de Nota",$A$19,"Grupo",$A27,"Laboratorio",B$26) -> 88.3 | C27: =GETPIVOTDATA("Promedio de Nota",$A$19,"Grupo",$A27,"Laboratorio",C$26) -> 87.5 | D27: =GETPIVOTDATA("Promedio de Nota",$A$19,"Grupo",$A27,"Laboratorio",D$26) -> 71 | E27: =GETPIVOTDATA("Promedio de Nota",$A$19,"Grupo",$A27,"Laboratorio",E$26) -> 86.5 | F27: =GETPIVOTDATA("Promedio de Nota",$A$19,"Grupo",$A27,"Laboratorio",F$26) -> 87.9
A28: GS124 | B28: =GETPIVOTDATA("Promedio de Nota",$A$19,"Grupo",$A28,"Laboratorio",B$26) -> 63.1 | C28: =GETPIVOTDATA("Promedio de Nota",$A$19,"Grupo",$A28,"Laboratorio",C$26) -> 64.8 | D28: =GETPIVOTDATA("Promedio de Nota",$A$19,"Grupo",$A28,"Laboratorio",D$26) -> 62 | E28: =GETPIVOTDATA("Promedio de Nota",$A$19,"Grupo",$A28,"Laboratorio",E$26) -> 67.7 | F28: =GETPIVOTDATA("Promedio de Nota",$A$19,"Grupo",$A28,"Laboratorio",F$26) -> 67.3
A29: GS126 | B29: =GETPIVOTDATA("Promedio de Nota",$A$19,"Grupo",$A29,"Laboratorio",B$26) -> 96.1 | C29: =GETPIVOTDATA("Promedio de Nota",$A$19,"Grupo",$A29,"Laboratorio",C$26) -> 89.6 | D29: =GETPIVOTDATA("Promedio de Nota",$A$19,"Grupo",$A29,"Laboratorio",D$26) -> 83.1 | E29: =GETPIVOTDATA("Promedio de Nota",$A$19,"Grupo",$A29,"Laboratorio",E$26) -> 89.7 | F29: =GETPIVOTDATA("Promedio de Nota",$A$19,"Grupo",$A29,"Laboratorio",F$26) -> 89.2
A31: Idiom A – Barras agrupadas (datos con PROMEDIO.SI.CONJUNTO)
A32: Laboratorio | B32: GS123 | C32: GS124 | D32: GS126
A33: Lab1 | B33: =AVERAGEIFS(Promedio_Grupo_Lab!$C$2:$C$16,Promedio_Grupo_Lab!$A$2:$A$16,B$32,Promedio_Grupo_Lab!$B$2:$B$16,$A33) -> 88.3 | C33: =AVERAGEIFS(Promedio_Grupo_Lab!$C$2:$C$16,Promedio_Grupo_Lab!$A$2:$A$16,C$32,Promedio_Grupo_Lab!$B$2:$B$16,$A33) -> 63.1 | D33: =AVERAGEIFS(Promedio_Grupo_Lab!$C$2:$C$16,Promedio_Grupo_Lab!$A$2:$A$16,D$32,Promedio_Grupo_Lab!$B$2:$B$16,$A33) -> 96.1
A34: Lab2 | B34: =AVERAGEIFS(Promedio_Grupo_Lab!$C$2:$C$16,Promedio_Grupo_Lab!$A$2:$A$16,B$32,Promedio_Grupo_Lab!$B$2:$B$16,$A34) -> 87.5 | C34: =AVERAGEIFS(Promedio_Grupo_Lab!$C$2:$C$16,Promedio_Grupo_Lab!$A$2:$A$16,C$32,Promedio_Grupo_Lab!$B$2:$B$16,$A34) -> 64.8 | D34: =AVERAGEIFS(Promedio_Grupo_Lab!$C$2:$C$16,Promedio_Grupo_Lab!$A$2:$A$16,D$32,Promedio_Grupo_Lab!$B$2:$B$16,$A34) -> 89.6
A35: Lab3 | B35: =AVERAGEIFS(Promedio_Grupo_Lab!$C$2:$C$16,Promedio_Grupo_Lab!$A$2:$A$16,B$32,Promedio_Grupo_Lab!$B$2:$B$16,$A35) -> 71 | C35: =AVERAGEIFS(Promedio_Grupo_Lab!$C$2:$C$16,Promedio_Grupo_Lab!$A$2:$A$16,C$32,Promedio_Grupo_Lab!$B$2:$B$16,$A35) -> 62 | D35: =AVERAGEIFS(Promedio_Grupo_Lab!$C$2:$C$16,Promedio_Grupo_Lab!$A$2:$A$16,D$32,Promedio_Grupo_Lab!$B$2:$B$16,$A35) -> 83.1
A36: Lab4 | B36: =AVERAGEIFS(Promedio_Grupo_Lab!$C$2:$C$16,Promedio_Grupo_Lab!$A$2:$A$16,B$32,Promedio_Grupo_Lab!$B$2:$B$16,$A36) -> 86.5 | C36: =AVERAGEIFS(Promedio_Grupo_Lab!$C$2:$C$16,Promedio_Grupo_Lab!$A$2:$A$16,C$32,Promedio_Grupo_Lab!$B$2:$B$16,$A36) -> 67.7 | D36: =AVERAGEIFS(Promedio_Grupo_Lab!$C$2:$C$16,Promedio_Grupo_Lab!$A$2:$A$16,D$32,Promedio_Grupo_Lab!$B$2:$B$16,$A36) -> 89.7
A37: Lab5 | B37: =AVERAGEIFS(Promedio_Grupo_Lab!$C$2:$C$16,Promedio_Grupo_Lab!$A$2:$A$16,B$32,Promedio_Grupo_Lab!$B$2:$B$16,$A37) -> 87.9 | C37: =AVERAGEIFS(Promedio_Grupo_Lab!$C$2:$C$16,Promedio_Grupo_Lab!$A$2:$A$16,C$32,Promedio_Grupo_Lab!$B$2:$B$16,$A37) -> 67.3 | D37: =AVERAGEIFS(Promedio_Grupo_Lab!$C$2:$C$16,Promedio_Grupo_Lab!$A$2:$A$16,D$32,Promedio_Grupo_Lab!$B$2:$B$16,$A37) -> 89.2
A39: Verificación manual – GS124
A40: Grupo analizado | B40: GS124
A41: Laboratorio | B41: Promedio (PROMEDIO.SI.CONJUNTO)
A42: =A33 -> Lab1 | B42: =AVERAGEIFS(Promedio_Grupo_Lab!$C$2:$C$16,Promedio_Grupo_Lab!$A$2:$A$16,$B$40,Promedio_Grupo_Lab!$B$2:$B$16,A42) -> 63.1
A43: =A34 -> Lab2 | B43: =AVERAGEIFS(Promedio_Grupo_Lab!$C$2:$C$16,Promedio_Grupo_Lab!$A$2:$A$16,$B$40,Promedio_Grupo_Lab!$B$2:$B$16,A43) -> 64.8
A44: =A35 -> Lab3 | B44: =AVERAGEIFS(Promedio_Grupo_Lab!$C$2:$C$16,Promedio_Grupo_Lab!$A$2:$A$16,$B$40,Promedio_Grupo_Lab!$B$2:$B$16,A44) -> 62
A45: =A36 -> Lab4 | B45: =AVERAGEIFS(Promedio_Grupo_Lab!$C$2:$C$16,Promedio_Grupo_Lab!$A$2:$A$16,$B$40,Promedio_Grupo_Lab!$B$2:$B$16,A45) -> 67.7
A46: =A37 -> Lab5 | B46: =AVERAGEIFS(Promedio_Grupo_Lab!$C$2:$C$16,Promedio_Grupo_Lab!$A$2:$A$16,$B$40,Promedio_Grupo_Lab!$B$2:$B$16,A46) -> 67.3
A47: Promedio mínimo (MIN) | B47: =MIN(B42:B46) -> 62
A48: Lab con más dificultad | B48: =INDEX(A42:A46,MATCH(B47,B42:B46,0)) -> Lab3
...
